<?xml version="1.0"?>
<robot name="robot_tubes_uro">
    <material name="green">
        <color rgba="0.0 0.8 0.0 1"/>
    </material>
    <material name="blue">
        <color rgba="0.0 0.0 0.8 1"/>
    </material>
    <material name="grey">
        <color rgba="0.5 0.5 0.5 1"/>
    </material>
    <link name="badan_robot">
        <visual>
            <geometry>
                <box size="0.6 0.4 0.2"/>
            </geometry>
            <origin xyz="0.0 0.0 0.0" rpy="0.0 0.0 0.0"/>
            <material name="blue" />
        </visual>
    </link>
    <link name="kepala_robot">
        <visual>
            <geometry>
                <cylinder radius="0.1" length="0.05"/>
            </geometry>
            <material name="green"/>
        </visual>
    </link>
    <link name="left_wheel_front">
        <visual>
            <geometry>
                <cylinder radius="0.1" length="0.05"/>
            </geometry>
            <origin xyz="0.0 0.0 0.0" rpy="1.6 0.0 0.0"/>
            <material name="grey"/>
        </visual>
    </link>
    <link name="right_wheel_front">
        <visual>
            <geometry>
                <cylinder radius="0.1" length="0.05"/>
            </geometry>
            <origin xyz="0.0 0.0 0.0" rpy="1.6 0.0 0.0"/>
            <material name="grey"/>
        </visual>
    </link>
    <link name="left_wheel_back">
        <visual>
            <geometry>
                <cylinder radius="0.1" length="0.05"/>
            </geometry>
            <origin xyz="0.0 0.0 0.0" rpy="1.6 0.0 0.0"/>
            <material name="grey"/>
        </visual>
    </link>
    <link name="right_wheel_back">
        <visual>
            <geometry>
                <cylinder radius="0.1" length="0.05"/>
            </geometry>
            <origin xyz="0.0 0.0 0.0" rpy="1.6 0.0 0.0"/>
            <material name="grey"/>
        </visual>
    </link>
    <joint name="kepala_robot_joint" type="fixed">
        <parent link="badan_robot"/>
        <child link="kepala_robot"/>
        <origin xyz="0.0 0.0 0.1" rpy="0.0 0.0 0.0"/>
    </joint>

    <joint name="left_wheel_front_joint" type="continuous">
        <parent link="badan_robot"/>
        <child link="left_wheel_front"/>
        <axis xyz="0.0 1.0 0.0"/>
        <origin xyz="-0.2 0.23 -0.1" rpy="0.0 0.0 0.0"/>
    </joint>

    <joint name="right_wheel_front_joint" type="continuous">
        <parent link="badan_robot"/>
        <child link="right_wheel_front"/>
        <axis xyz="0.0 1.0 0.0"/>
        <origin xyz="-0.2 -0.23 -0.1" rpy="0.0 0.0 0.0"/>
    </joint>

    <joint name="left_wheel_back_joint" type="continuous">
        <parent link="badan_robot"/>
        <child link="left_wheel_back"/>
        <axis xyz="0.0 1.0 0.0"/>
        <origin xyz="0.2 0.23 -0.1" rpy="0.0 0.0 0.0"/>
    </joint>

    <joint name="right_wheel_back_joint" type="continuous">
        <parent link="badan_robot"/>
        <child link="right_wheel_back"/>
        <axis xyz="0.0 1.0 0.0"/>
        <origin xyz="0.2 -0.23 -0.1" rpy="0.0 0.0 0.0"/>
    </joint>
</robot>
