<?xml version="1.0"?>
<robot name="robot_tubes_uro" xmlns:xacro="http://www.ros.org/wiki/xacro">

    <!-- Define materials -->
    <material name="green">
        <color rgba="0.0 0.8 0.0 1"/>
    </material>
    <material name="blue">
        <color rgba="0.0 0.0 0.8 1"/>
    </material>
    <material name="grey">
        <color rgba="0.5 0.5 0.5 1"/>
    </material>

    <!-- Define common wheel properties -->
    <xacro:macro name="wheel" params="name x_offset y_offset z_offset">
        <link name="${name}">
            <visual>
                <geometry>
                    <cylinder radius="0.1" length="0.05"/>
                </geometry>
                <origin xyz="0.0 0.0 0.0" rpy="1.57 0.0 0.0"/>
                <material name="grey"/>
            </visual>
            <collision>
                <geometry>
                    <cylinder radius="0.1" length="0.05"/>
                </geometry>
                <origin xyz="0.0 0.0 0.0" rpy="1.57 0.0 0.0"/>
            </collision>
            <inertial>
                <mass value="1.0"/>
                <inertia ixx="0.01" ixy="0.0" ixz="0.0" iyy="0.01" iyz="0.0" izz="0.005"/>
            </inertial>
        </link>
    </xacro:macro>

    <!-- Define body and head -->
    <link name="badan_robot">
        <visual>
            <geometry>
                <box size="0.6 0.4 0.2"/>
            </geometry>
            <origin xyz="0.0 0.0 0.0" rpy="0.0 0.0 0.0"/>
            <material name="blue"/>
        </visual>
        <collision>
            <geometry>
                <box size="0.6 0.4 0.2"/>
            </geometry>
        </collision>
        <inertial>
            <mass value="5.0"/>
            <inertia ixx="0.1" ixy="0.0" ixz="0.0" iyy="0.1" iyz="0.0" izz="0.1"/>
        </inertial>
    </link>

    <link name="kepala_robot">
        <visual>
            <geometry>
                <cylinder radius="0.1" length="0.05"/>
            </geometry>
            <origin xyz="0.0 0.0 0.0" rpy="0.0 0.0 0.0"/>
            <material name="green"/>
        </visual>
        <collision>
            <geometry>
                <cylinder radius="0.1" length="0.05"/>
            </geometry>
        </collision>
        <inertial>
            <mass value="0.5"/>
            <inertia ixx="0.002" ixy="0.0" ixz="0.0" iyy="0.002" iyz="0.0" izz="0.001"/>
        </inertial>
    </link>

    <!-- Use wheel macro for front and back wheels -->
    <xacro:wheel name="left_wheel_front" x_offset="-0.2" y_offset="0.23" z_offset="-0.1"/>
    <xacro:wheel name="right_wheel_front" x_offset="-0.2" y_offset="-0.23" z_offset="-0.1"/>
    <xacro:wheel name="left_wheel_back" x_offset="0.2" y_offset="0.23" z_offset="-0.1"/>
    <xacro:wheel name="right_wheel_back" x_offset="0.2" y_offset="-0.23" z_offset="-0.1"/>

    <!-- Define joints -->
    <joint name="kepala_robot_joint" type="fixed">
        <parent link="badan_robot"/>
        <child link="kepala_robot"/>
        <origin xyz="0.0 0.0 0.1" rpy="0.0 0.0 0.0"/>
    </joint>

    <joint name="left_wheel_front_joint" type="continuous">
        <parent link="badan_robot"/>
        <child link="left_wheel_front"/>
        <origin xyz="-0.2 0.23 -0.1" rpy="0.0 0.0 0.0"/>
        <axis xyz="0.0 1.0 0.0"/>
    </joint>

    <joint name="right_wheel_front_joint" type="continuous">
        <parent link="badan_robot"/>
        <child link="right_wheel_front"/>
        <origin xyz="-0.2 -0.23 -0.1" rpy="0.0 0.0 0.0"/>
        <axis xyz="0.0 1.0 0.0"/>
    </joint>

    <joint name="left_wheel_back_joint" type="continuous">
        <parent link="badan_robot"/>
        <child link="left_wheel_back"/>
        <origin xyz="0.2 0.23 -0.1" rpy="0.0 0.0 0.0"/>
        <axis xyz="0.0 1.0 0.0"/>
    </joint>

    <joint name="right_wheel_back_joint" type="continuous">
        <parent link="badan_robot"/>
        <child link="right_wheel_back"/>
        <origin xyz="0.2 -0.23 -0.1" rpy="0.0 0.0 0.0"/>
        <axis xyz="0.0 1.0 0.0"/>
    </joint>
    <link name="dummy_root">
    <inertial>
        <mass value="0.001"/>
        <inertia ixx="1e-6" ixy="0" ixz="0" iyy="1e-6" iyz="0" izz="1e-6"/>
    </inertial>
</link>

<joint name="dummy_root_joint" type="fixed">
    <parent link="dummy_root"/>
    <child link="badan_robot"/>
    <origin xyz="0 0 0" rpy="0 0 0"/>
</joint>

</robot>
